Workbook

Sheet Leia Primeiro
A1: ANALISTA JÚNIOR COM IA | Material de Apoio – Módulo 3
A3: Sobre este arquivo
A4: Este arquivo foi criado especialmente para acompanhar o Módulo 3 do livro Analista Júnior com IA. Ele usa dados reais do IF.data, o portal oficial de dados do Banco Central do Brasil, com informações de setembro de 2025 sobre todas as instituições financeiras autorizadas a funcionar no país.
A6: Como navegar pelo arquivo
A8: 📋 Leia Primeiro | B8: Esta aba. Leia antes de começar.
A9: 📊 Base_IFdata | B9: Base de dados real com as 100 maiores instituições financeiras do Brasil (IF.data, set/2025). Use para todos os exercícios.
A10: 📖 Dicionário | B10: Explicação de cada coluna e código da base. Sempre consulte antes de analisar.
A11: 🔢 Exerc_Básico | B11: Exercícios de fórmulas básicas com a base real. Nível: iniciante.
A12: 📈 Exerc_Intermediário | B12: Análises mais complexas: MÉDIASE, SOMASES, classificação e tabela dinâmica.
A13: 📝 Template_Análise | B13: Template para você construir sua análise final e apresentar os resultados.
A15: Dicas de uso com Claude.ai
A16: 1. | B16: Cole um trecho dos dados e peça: 'O que cada coluna significa para um analista financeiro?'
A17: 2. | B17: Se travar em uma fórmula: 'Estou tentando calcular X com os dados Y. Qual fórmula usar no Excel?'
A18: 3. | B18: Ao terminar a análise, cole seus insights e peça: 'Como eu comunicaria isso de forma clara para um gestor?'

Sheet Dicionário
A1: DICIONÁRIO DE DADOS | IF.data – Banco Central do Brasil
A3: Colunas da base de dados
A4: Coluna | B4: Nome completo | C4: Tipo | D4: O que significa na prática
A5: Instituição | B5: Nome da instituição financeira | C5: Texto | D5: Nome do banco, fintech, cooperativa ou instituição de pagamento cadastrada no Banco Central.
A6: TCB | B6: Tipo de Consolidado Bancário | C6: Código | D6: Classifica o tipo de instituição. b1 = banco comercial/múltiplo com carteira comercial (os grandes bancos); n4 = instituição de pagamento (Nubank, PicPay, Mercado Pago); b3S = cooperativa singular.
A7: SR | B7: Segmento Resolução nº 4.553/2017 | C7: Código | D7: Classifica o porte da instituição: S1 é o maior (Itaú, BB, Caixa, Bradesco, Santander), S5 é o menor. Define o nível de exigências regulatórias.
A8: TC | B8: Tipo de Controle | C8: Código | D8: 1 = Público (BB, Caixa, BNB, BNDES); 2 = Privado Nacional (Itaú, Bradesco, Nubank); 3 = Privado com Controle Estrangeiro (Santander, Citibank, JP Morgan).
A9: TD | B9: Tipo de Consolidação | C9: Código | D9: C = Conglomerado (o grupo financeiro consolidado); I = Instituição independente (instituição individual sem grupo).
A10: Cidade / UF | B10: Localização da sede | C10: Texto | D10: Cidade e estado onde a instituição tem sua sede principal registrada no Banco Central.
A11: Data | B11: Data de referência | C11: Texto | D11: Mês e ano dos dados. 09/2025 = posição de setembro de 2025.
A12: Ativo Total | B12: Total de ativos (R$ mil) | C12: Número | D12: Tudo que a instituição possui: créditos concedidos, títulos, imóveis, participações. É o principal indicador de porte de um banco.
A13: Carteira de Crédito | B13: Total de créditos concedidos (R$ mil) | C13: Número | D13: Soma de todos os empréstimos, financiamentos e créditos concedidos pela instituição a clientes. É a atividade-fim dos bancos comerciais.
A14: TVM | B14: Títulos e Valores Mobiliários (R$ mil) | C14: Número | D14: Investimentos da instituição em títulos públicos (Tesouro), títulos privados, ações e outros ativos financeiros.
A15: Passivo Exigível | B15: Total de obrigações (R$ mil) | C15: Número | D15: Tudo que a instituição deve: depósitos de clientes, captações, dívidas. A diferença entre Ativo Total e Passivo Exigível é aproximadamente o Patrimônio Líquido.
... A22: ROE | B22: Retorno sobre Patrimônio Líquido | C22: Fórmula | D22: Calculado: Lucro Líquido / Patrimônio Líquido. Mede a eficiência da instituição em gerar lucro com o capital próprio. Referência: ROE acima de 15% é considerado bom no setor.
A24: Códigos de classificação (TCB, SR, TC)
A25: Código | B25: Categoria | C25: Descrição completa | D25: Exemplos
A26: b1 | B26: TCB | C26: Banco Comercial, Banco Múltiplo com Carteira Comercial ou Caixa Econômica | D26: Itaú, BB, Caixa, Bradesco, Santander, Nubank (banco)
A27: b2 | B27: TCB | C27: Banco Múltiplo sem Carteira Comercial, Banco de Investimento ou Câmbio | D27: Goldman Sachs, Banco Volkswagen, Stellantis
A28: b3S | B28: TCB | C28: Cooperativa de Crédito Singular | D28: Sicredi (cooperativas individuais), Sicoob singular
A29: b3C | B29: TCB | C29: Central e Confederação de Cooperativas de Crédito | D29: Sicoob Central, Sicredi Central
A30: b4 | B30: TCB | C30: Banco de Desenvolvimento | D30: BNDES, BNB, BRDE, Banco da Amazônia
A31: n1 | B31: TCB | C31: Não Bancário de Crédito (financeiras, SCDs) | D31: Porto Seguro Financeiro, Stone Financeiro
A32: n2 | B32: TCB | C32: Não Bancário de Mercado de Capitais (corretoras, DTVM) | D32: Corretoras de câmbio e valores
A33: n4 | B33: TCB | C33: Instituição de Pagamento | D33: Mercado Pago, PicPay, Cielo, Stone IP, PagSeguro
A34: S1 | B34: SR | C34: Segmento 1 – Porte sistêmico (> 10% do PIB ou atividade internacional) | D34: Itaú, BB, Caixa, Bradesco, Santander
A35: S2 | B35: SR | C35: Segmento 2 – Porte grande (> 1% do PIB) | D35: BNDES, BTG Pactual, XP, Safra, Nubank
A36: S3 | B36: SR | C36: Segmento 3 – Porte médio | D36: Daycoval, Inter, BRB, BMG, ABC-Brasil
... A41: 3 | B41: TC | C41: Controle Privado Estrangeiro | D41: Santander (ES), Citibank (EUA), JP Morgan (EUA), BNP Paribas (FR)

Sheet Base_IFdata
A1: BASE DE DADOS – IF.DATA | Banco Central do Brasil | Setembro 2025 | Valores em R$ mil
A2: Fonte: https://www3.bcb.gov.br/ifdata | 100 maiores instituições por Ativo Total | Dados reais do sistema financeiro brasileiro
A4: Instituição | C4: TCB | D4: Segmento (SR) | E4: Controle (TC) | F4: Cidade | G4: UF | H4: Ativo Total (R$ mil) | I4: Carteira de Crédito (R$ mil) | J4: TVM (R$ mil) | K4: Passivo (R$ mil) | L4: Captações (R$ mil) | M4: Patrimônio Líquido (R$ mil) | N4: Lucro Líquido (R$ mil) | O4: Agências | P4: Postos | Q4: Tipo Instituição | R4: Tipo Controle | S4: Índice Crédito/ Ativo (%) | T4: ROE (%)
A5: BANCO NACIONAL DE DESENVOLVIMENTO ECONOMICO E SOCI | B5: =IF(H5>= 100000000, "Grande", "Média/Pequena" ) -> Grande | C5: b4 | D5: S2 | E5: 1 | F5: RIO DE JANEIRO | G5: RJ | H5: 905220074 | I5: 337101530 | J5: 163600304 | K5: 736690922 | L5: 596672518 | M5: 168529152 | N5: 3897466 | O5: 5 | Q5: Banco de Desenvolvimento | R5: Público | S5: =I5/H5 -> 0.37239732 | T5: =N5/M5 -> 0.023126361 | U5: {=_xlfn.IFS(T5:T104>15%,"Excelente",T5:T104>8%,"Bom",T5:T104>0%,"Fraco",T5:T104<=0%,"Prejuizo")} -> Fraco
A6: BTG PACTUAL | B6: =IF(H6>= 100000000, "Grande", "Média/Pequena" ) -> Grande | C6: b1 | D6: S1 | E6: 2 | F6: RIO DE JANEIRO | G6: RJ | H6: 665445894 | I6: 168426944 | J6: 205485096 | K6: 597330797 | L6: 460048347 | M6: 68115098 | N6: 4337377 | O6: 66 | Q6: Banco Comercial / Múltiplo c/ Carteira C | R6: Privado Nacional | S6: =I6/H6 -> 0.25310389 | T6: =N6/M6 -> 0.063677175 | U6: Fraco
A7: XP | B7: =IF(H7>= 100000000, "Grande", "Média/Pequena" ) -> Grande | C7: b1 | D7: S2 | E7: 2 | F7: RIO DE JANEIRO | G7: RJ | H7: 307101659 | I7: 33329722 | J7: 109000669 | K7: 294990308 | L7: 219008553 | M7: 12111351 | N7: 205279 | O7: 11 | Q7: Banco Comercial / Múltiplo c/ Carteira C | R7: Privado Nacional | S7: =I7/H7 -> 0.10852993 | T7: =N7/M7 -> 0.016949306 | U7: Fraco
A8: SAFRA | B8: =IF(H8>= 100000000, "Grande", "Média/Pequena" ) -> Grande | C8: b1 | D8: S2 | E8: 2 | F8: SAO PAULO | G8: SP | H8: 271094929 | I8: 132708479 | J8: 69307857 | K8: 252005262 | L8: 207723576 | M8: 19089667 | N8: 1128996 | O8: 188 | P8: 3 | Q8: Banco Comercial / Múltiplo c/ Carteira C | R8: Privado Nacional | S8: =I8/H8 -> 0.48952771 | T8: =N8/M8 -> 0.059141734 | U8: Fraco
A9: NUBANK | B9: =IF(H9>= 100000000, "Grande", "Média/Pequena" ) -> Grande | C9: n1 | D9: S2 | E9: 3 | F9: SAO PAULO | G9: SP | H9: 219449385 | I9: 61661647 | J9: 65169820 | K9: 207181651 | L9: 186790022 | M9: 12267733 | N9: 2198336 | O9: 4 | Q9: Não Bancário de Crédito | R9: Privado Estrangeiro | S9: =I9/H9 -> 0.28098346 | T9: =N9/M9 -> 0.1791966 | U9: Excelente
A10: BANCO COOPERATIVO SICREDI S.A. | B10: =IF(H10>= 100000000, "Grande", "Média/Pequena" ) -> Grande | C10: b1 | D10: S2 | E10: 2 | F10: PORTO ALEGRE | G10: RS | H10: 218490737 | I10: 42609275 | J10: 57996229 | K10: 213011964 | L10: 188480581 | M10: 5478773 | N10: 15778 | O10: 6 | Q10: Banco Comercial / Múltiplo c/ Carteira C | R10: Privado Nacional | S10: =I10/H10 -> 0.19501639 | T10: =N10/M10 -> 0.0028798419 | U10: Fraco
A11: BANCO SICOOB | B11: =IF(H11>= 100000000, "Grande", "Média/Pequena" ) -> Grande | C11: b1 | D11: S2 | E11: 2 | F11: BRASILIA | G11: DF | H11: 201784998 | I11: 38031688 | J11: 41539239 | K11: 196149070 | L11: 172714942 | M11: 5635928 | N11: 135356 | O11: 7 | Q11: Banco Comercial / Múltiplo c/ Carteira C | R11: Privado Nacional | S11: =I11/H11 -> 0.18847629 | T11: =N11/M11 -> 0.02401663 | U11: Fraco
A12: CITIBANK | B12: =IF(H12>= 100000000, "Grande", "Média/Pequena" ) -> Grande | C12: b1 | D12: S2 | E12: 3 | F12: SAO PAULO | G12: SP | H12: 200077288 | I12: 31540925 | J12: 50921410 | K12: 185601125 | L12: 153215374 | M12: 14476163 | N12: 900878 | O12: 53 | P12: 8 | Q12: Banco Comercial / Múltiplo c/ Carteira C | R12: Privado Estrangeiro | S12: =I12/H12 -> 0.15764371 | T12: =N12/M12 -> 0.062231822 | U12: Fraco
A13: BANRISUL | B13: =IF(H13>= 100000000, "Grande", "Média/Pequena" ) -> Grande | C13: b1 | D13: S2 | E13: 1 | F13: PORTO ALEGRE | G13: RS | H13: 158217683 | I13: 60523673 | J13: 66985961 | K13: 147341800 | L13: 135080299 | M13: 10875884 | N13: 328616 | O13: 514 | P13: 43 | Q13: Banco Comercial / Múltiplo c/ Carteira C | R13: Público | S13: =I13/H13 -> 0.38253419 | T13: =N13/M13 -> 0.030215107 | U13: Fraco
A14: VOTORANTIM | B14: =IF(H14>= 100000000, "Grande", "Média/Pequena" ) -> Grande | C14: b1 | D14: S2 | E14: 2 | F14: SAO PAULO | G14: SP | H14: 149358844 | I14: 73288335 | J14: 37221208 | K14: 136468541 | L14: 110051230 | M14: 12890303 | N14: 457848 | O14: 7 | P14: 3 | Q14: Banco Comercial / Múltiplo c/ Carteira C | R14: Privado Nacional | S14: =I14/H14 -> 0.49068628 | T14: =N14/M14 -> 0.035518793 | U14: Fraco
A15: REDECARD INSTITUIÇÃO DE PAGAMENTO S.A. | B15: =IF(H15>= 100000000, "Grande", "Média/Pequena" ) -> Grande | C15: n4 | D15: S1 | E15: 2 | F15: SAO PAULO | G15: SP | H15: 137122969 | J15: 8287550 | K15: 98343078 | L15: 1478 | M15: 38779891 | N15: 917240 | O15: 1 | Q15: Instituição de Pagamento | R15: Privado Nacional | S15: =I15/H15 -> 0 | T15: =N15/M15 -> 0.023652465 | U15: Fraco
A16: C6 BANK | B16: =IF(H16>= 100000000, "Grande", "Média/Pequena" ) -> Grande | C16: b1 | D16: S3 | E16: 2 | F16: SAO PAULO | G16: SP | H16: 134136879 | I16: 81749998 | J16: 34316499 | K16: 128508996 | L16: 93233153 | M16: 5627883 | N16: 634846 | O16: 6 | Q16: Banco Comercial / Múltiplo c/ Carteira C | R16: Privado Nacional | S16: =I16/H16 -> 0.60945207 | T16: =N16/M16 -> 0.1128037 | U16: Bom
A17: CIELO S.A. - INSTITUIÇÃO DE PAGAMENTO | B17: =IF(H17>= 100000000, "Grande", "Média/Pequena" ) -> Grande | C17: n4 | D17: NA | E17: 2 | F17: BARUERI | G17: SP | H17: 114886546 | J17: 9277619 | K17: 104649265 | L17: 10716782 | M17: 10237281 | N17: 343972 | O17: 1 | Q17: Instituição de Pagamento | R17: Privado Nacional | S17: =I17/H17 -> 0 | T17: =N17/M17 -> 0.033599937 | U17: Fraco
A18: JP MORGAN CHASE | B18: =IF(H18>= 100000000, "Grande", "Média/Pequena" ) -> Grande | C18: b1 | D18: S3 | E18: 3 | F18: SAO PAULO | G18: SP | H18: 108602030 | I18: 2123945 | J18: 46332669 | K18: 95483657 | L18: 80007018 | M18: 13118373 | N18: 553831 | O18: 9 | Q18: Banco Comercial / Múltiplo c/ Carteira C | R18: Privado Estrangeiro | S18: =I18/H18 -> 0.019557139 | T18: =N18/M18 -> 0.042217964 | U18: Fraco
A19: NU PAGAMENTOS S.A. - INSTITUIÇÃO DE PAGAMENTO | B19: =IF(H19>= 100000000, "Grande", "Média/Pequena" ) -> Grande | C19: n4 | D19: S2 | E19: 3 | F19: SAO PAULO | G19: SP | H19: 103307891 | I19: 61461123 | J19: 616461 | K19: 83974937 | L19: 8385269 | M19: 19332954 | N19: 2902783 | O19: 1 | Q19: Instituição de Pagamento | R19: Privado Estrangeiro | S19: =I19/H19 -> 0.59493154 | T19: =N19/M19 -> 0.15014689 | U19: Excelente
A20: DAYCOVAL | B20: =IF(H20>= 100000000, "Grande", "Média/Pequena" ) -> Média/Pequena | C20: b1 | D20: S3 | E20: 2 | F20: SAO PAULO | G20: SP | H20: 90792081 | I20: 52257443 | J20: 20464231 | K20: 82811660 | L20: 73619583 | M20: 7980420 | N20: 473258 | O20: 60 | Q20: Banco Comercial / Múltiplo c/ Carteira C | R20: Privado Nacional | S20: =I20/H20 -> 0.5755727 | T20: =N20/M20 -> 0.059302393 | U20: Fraco
A21: INTER | B21: =IF(H21>= 100000000, "Grande", "Média/Pequena" ) -> Média/Pequena | C21: b1 | D21: S3 | E21: 2 | F21: BELO HORIZONTE | G21: MG | H21: 89798255 | I21: 39109757 | J21: 26898298 | K21: 82451334 | L21: 69019589 | M21: 7346921 | N21: 288276 | O21: 4 | Q21: Banco Comercial / Múltiplo c/ Carteira C | R21: Privado Nacional | S21: =I21/H21 -> 0.43552914 | T21: =N21/M21 -> 0.039237662 | U21: Fraco
A22: MERCADO PAGO INSTITUIÇÃO DE PAGAMENTO LTDA. | B22: =IF(H22>= 100000000, "Grande", "Média/Pequena" ) -> Média/Pequena | C22: n4 | D22: S3 | E22: 3 | F22: OSASCO | G22: SP | H22: 83811718 | I22: 15083268 | J22: 12474813 | K22: 80429749 | L22: 38886398 | M22: 3381969 | N22: 225790 | O22: 1 | Q22: Instituição de Pagamento | R22: Privado Estrangeiro | S22: =I22/H22 -> 0.1799661 | T22: =N22/M22 -> 0.066762883 | U22: Fraco
A23: BRB | B23: =IF(H23>= 100000000, "Grande", "Média/Pequena" ) -> Média/Pequena | C23: b1 | D23: S3 | E23: 1 | F23: BRASILIA | G23: DF | H23: 81653988 | I23: 54825544 | J23: 13858351 | K23: 77133167 | L23: 69274647 | M23: 4520820 | N23: 184060 | O23: 69 | P23: 193 | Q23: Banco Comercial / Múltiplo c/ Carteira C | R23: Público | S23: =I23/H23 -> 0.67143743 | T23: =N23/M23 -> 0.040713853 | U23: Fraco
A24: STONE INSTITUIÇÃO DE PAGAMENTO S.A. | B24: =IF(H24>= 100000000, "Grande", "Média/Pequena" ) -> Média/Pequena | C24: n4 | D24: S3 | E24: 3 | F24: SAO PAULO | G24: SP | H24: 81421286 | J24: 28893421 | K24: 78709548 | L24: 29062647 | M24: 2711738 | N24: 94102 | O24: 1 | Q24: Instituição de Pagamento | R24: Privado Estrangeiro | S24: =I24/H24 -> 0 | T24: =N24/M24 -> 0.03470173 | U24: Fraco
A25: GETNET ADQUIRÊNCIA E SERVIÇOS PARA MEIOS DE PAGAME | B25: =IF(H25>= 100000000, "Grande", "Média/Pequena" ) -> Média/Pequena | C25: n4 | D25: S1 | E25: 3 | F25: SAO PAULO | G25: SP | H25: 75739273 | J25: 114927 | K25: 72438692 | L25: 545506 | M25: 3300581 | N25: 124935 | O25: 1 | Q25: Instituição de Pagamento | R25: Privado Estrangeiro | S25: =I25/H25 -> 0 | T25: =N25/M25 -> 0.037852427 | U25: Fraco
A26: BANCO DO NORDESTE DO BRASIL S.A. | B26: =IF(H26>= 100000000, "Grande", "Média/Pequena" ) -> Média/Pequena | C26: b1 | D26: S2 | E26: 1 | F26: FORTALEZA | G26: CE | H26: 71183557 | I26: 18694576 | J26: 43688126 | K26: 55662219 | L26: 21820106 | M26: 15521338 | N26: 657843 | O26: 301 | P26: 1 | Q26: Banco Comercial / Múltiplo c/ Carteira C | R26: Público | S26: =I26/H26 -> 0.26262492 | T26: =N26/M26 -> 0.042383137 | U26: Fraco
A27: PAGSEGURO INTERNET INSTITUIÇÃO DE PAGAMENTO S.A. | B27: =IF(H27>= 100000000, "Grande", "Média/Pequena" ) -> Média/Pequena | C27: n4 | D27: S3 | E27: 2 | F27: SAO PAULO | G27: SP | H27: 70658099 | I27: 570898 | J27: 4812581 | K27: 61347060 | L27: 43152758 | M27: 9311040 | N27: 241167 | O27: 1 | Q27: Instituição de Pagamento | R27: Privado Nacional | S27: =I27/H27 -> 0.0080797249 | T27: =N27/M27 -> 0.025901188 | U27: Fraco
A28: ABC-BRASIL | B28: =IF(H28>= 100000000, "Grande", "Média/Pequena" ) -> Média/Pequena | C28: b1 | D28: S3 | E28: 3 | F28: SAO PAULO | G28: SP | H28: 61037531 | I28: 20697873 | J28: 27404725 | K28: 54321463 | L28: 46150549 | M28: 6716068 | N28: 263010 | O28: 15 | Q28: Banco Comercial / Múltiplo c/ Carteira C | R28: Privado Estrangeiro | S28: =I28/H28 -> 0.33910076 | T28: =N28/M28 -> 0.039161307 | U28: Fraco
A29: BANCO DA AMAZONIA S.A. | B29: =IF(H29>= 100000000, "Grande", "Média/Pequena" ) -> Média/Pequena | C29: b1 | D29: S3 | E29: 1 | F29: BELEM | G29: PA | H29: 60398229 | I29: 35935979 | J29: 20362942 | K29: 53115179 | L29: 14740265 | M29: 7283049 | N29: 224768 | O29: 115 | Q29: Banco Comercial / Múltiplo c/ Carteira C | R29: Público | S29: =I29/H29 -> 0.59498399 | T29: =N29/M29 -> 0.0308618 | U29: Fraco
A30: BANCO VOLKSWAGEN S.A. | B30: =IF(H30>= 100000000, "Grande", "Média/Pequena" ) -> Média/Pequena | C30: b2 | D30: S3 | E30: 3 | F30: SAO PAULO | G30: SP | H30: 57305530 | I30: 47227707 | J30: 411875 | K30: 52194555 | L30: 45679270 | M30: 5110975 | N30: 52127 | O30: 2 | Q30: Banco Múltiplo s/ Cart. Comercial / Inve | R30: Privado Estrangeiro | S30: =I30/H30 -> 0.82413873 | T30: =N30/M30 -> 0.010199032 | U30: Fraco
A31: BANCO BNP PARIBAS BRASIL S.A. | B31: =IF(H31>= 100000000, "Grande", "Média/Pequena" ) -> Média/Pequena | C31: b1 | D31: S3 | E31: 3 | F31: SAO PAULO | G31: SP | H31: 53861163 | I31: 6435562 | J31: 25019318 | K31: 49130639 | L31: 34576722 | M31: 4730524 | N31: -14272 | O31: 2 | Q31: Banco Comercial / Múltiplo c/ Carteira C | R31: Privado Estrangeiro | S31: =I31/H31 -> 0.11948427 | T31: =N31/M31 -> -0.0030170019 | U31: Prejuizo
A32: BANCO RABOBANK INTERNATIONAL BRASIL S.A. | B32: =IF(H32>= 100000000, "Grande", "Média/Pequena" ) -> Média/Pequena | C32: b1 | D32: S3 | E32: 3 | F32: SAO PAULO | G32: SP | H32: 53243129 | I32: 35929923 | J32: 5428626 | K32: 47436684 | L32: 42473991 | M32: 5806445 | N32: 133564 | O32: 19 | Q32: Banco Comercial / Múltiplo c/ Carteira C | R32: Privado Estrangeiro | S32: =I32/H32 -> 0.67482741 | T32: =N32/M32 -> 0.023002715 | U32: Fraco
A33: BMG | B33: =IF(H33>= 100000000, "Grande", "Média/Pequena" ) -> Média/Pequena | C33: b1 | D33: S3 | E33: 2 | F33: SAO PAULO | G33: SP | H33: 48654470 | I33: 21826968 | J33: 16044068 | K33: 44808273 | L33: 34121921 | M33: 3846197 | N33: 148265 | O33: 35 | P33: 2 | Q33: Banco Comercial / Múltiplo c/ Carteira C | R33: Privado Nacional | S33: =I33/H33 -> 0.44861177 | T33: =N33/M33 -> 0.038548467 | U33: Fraco
A34: PAGBANK-PAGSEGURO | B34: =IF(H34>= 100000000, "Grande", "Média/Pequena" ) -> Média/Pequena | C34: b1 | D34: S3 | E34: 2 | F34: SAO PAULO | G34: SP | H34: 47121104 | I34: 42705618 | J34: 350110 | K34: 45731566 | L34: 45436982 | M34: 1389538 | N34: 12156 | O34: 4 | Q34: Banco Comercial / Múltiplo c/ Carteira C | R34: Privado Nacional | S34: =I34/H34 -> 0.90629494 | T34: =N34/M34 -> 0.0087482314 | U34: Fraco
A35: AGIBANK | B35: =IF(H35>= 100000000, "Grande", "Média/Pequena" ) -> Média/Pequena | C35: b1 | D35: S3 | E35: 2 | F35: CAMPINAS | G35: SP | H35: 46039242 | I35: 32156062 | J35: 8673021 | K35: 42980647 | L35: 30299489 | M35: 3058595 | N35: 222644 | O35: 4 | P35: 318 | Q35: Banco Comercial / Múltiplo c/ Carteira C | R35: Privado Nacional | S35: =I35/H35 -> 0.69844899 | T35: =N35/M35 -> 0.0727929 | U35: Fraco
A36: BOFA MERRILL LYNCH | B36: =IF(H36>= 100000000, "Grande", "Média/Pequena" ) -> Média/Pequena | C36: b1 | D36: S3 | E36: 3 | F36: SAO PAULO | G36: SP | H36: 39477159 | I36: 2319542 | J36: 9631104 | K36: 32577440 | L36: 22798787 | M36: 6899720 | N36: 254132 | O36: 3 | Q36: Banco Comercial / Múltiplo c/ Carteira C | R36: Privado Estrangeiro | S36: =I36/H36 -> 0.058756558 | T36: =N36/M36 -> 0.036832219 | U36: Fraco
A37: BANESTES | B37: =IF(H37>= 100000000, "Grande", "Média/Pequena" ) -> Média/Pequena | C37: b1 | D37: S3 | E37: 1 | F37: VITORIA | G37: ES | H37: 39224908 | I37: 12030223 | J37: 10490646 | K37: 36782556 | L37: 35293616 | M37: 2442351 | N37: 110665 | O37: 88 | P37: 62 | Q37: Banco Comercial / Múltiplo c/ Carteira C | R37: Público | S37: =I37/H37 -> 0.30669857 | T37: =N37/M37 -> 0.04531085 | U37: Fraco
A38: PICPAY - FINANCEIRO | B38: =IF(H38>= 100000000, "Grande", "Média/Pequena" ) -> Média/Pequena | C38: b1 | D38: S3 | E38: 2 | F38: SAO PAULO | G38: SP | H38: 36903126 | I38: 18692150 | J38: 9101147 | K38: 35579849 | L38: 28066944 | M38: 1323278 | N38: 44142 | O38: 7 | Q38: Banco Comercial / Múltiplo c/ Carteira C | R38: Privado Nacional | S38: =I38/H38 -> 0.50651942 | T38: =N38/M38 -> 0.03335807 | U38: Fraco
A39: GOLDMAN SACHS | B39: =IF(H39>= 100000000, "Grande", "Média/Pequena" ) -> Média/Pequena | C39: b2 | D39: S3 | E39: 3 | F39: SAO PAULO | G39: SP | H39: 35476399 | J39: 21278861 | K39: 30529349 | L39: 14735766 | M39: 4947050 | N39: 236535 | O39: 4 | Q39: Banco Múltiplo s/ Cart. Comercial / Inve | R39: Privado Estrangeiro | S39: =I39/H39 -> 0 | T39: =N39/M39 -> 0.047813343 | U39: Fraco
A40: BANCO CLASSICO S.A. | B40: =IF(H40>= 100000000, "Grande", "Média/Pequena" ) -> Média/Pequena | C40: b1 | D40: S3 | E40: 2 | F40: RIO DE JANEIRO | G40: RJ | H40: 35077310 | J40: 29886789 | K40: 16040614 | L40: 4622609 | M40: 19036696 | N40: 68896 | O40: 2 | Q40: Banco Comercial / Múltiplo c/ Carteira C | R40: Privado Nacional | S40: =I40/H40 -> 0 | T40: =N40/M40 -> 0.0036191154 | U40: Fraco
A41: BANCO ORIGINAL S.A. | B41: =IF(H41>= 100000000, "Grande", "Média/Pequena" ) -> Média/Pequena | C41: b1 | D41: S3 | E41: 2 | F41: SAO PAULO | G41: SP | H41: 33578473 | I41: 13581188 | J41: 11511218 | K41: 32114297 | L41: 29988027 | M41: 1464177 | N41: -14250 | O41: 2 | Q41: Banco Comercial / Múltiplo c/ Carteira C | R41: Privado Nacional | S41: =I41/H41 -> 0.40446116 | T41: =N41/M41 -> -0.0097324299 | U41: Prejuizo
...

Sheet Exemplos_Graficos
A1: EXEMPLOS DE GRÁFICOS | Analista Júnior com IA — Módulo 3 | IF.data Set/2025
A2: Cada gráfico abaixo foi criado com dados reais do IF.data usando apenas fórmulas e dados desta planilha. Siga os passos e reproduza no Excel.
A4: GRÁFICO 1 — Barras Verticais: ROE Médio por Segmento (%)
A5: Como criar: Selecione os dados abaixo (A:B) → Inserir → Gráfico de Colunas → Formatar eixos e cores
A6: Segmento | B6: ROE Médio (%) | C6: Nº Instituições | D6: Ativo Total (R$ bi)
A7: S1 | B7: 4.67 | C7: 4 | D7: 0.9
A8: S2 | B8: 4.33 | C8: 11 | D8: 2.8
A9: S3 | B9: 3.02 | C9: 63 | D9: 2.2
A10: S4 | B10: 3.83 | C10: 18 | D10: 0.2
A11: S5 | B11: 3.98 | C11: 3 | D11: 0
A29: GRÁFICO 2 — Pizza: Participação no Ativo Total por Tipo de Controle
A30: Como criar: Selecione Controle + Participação → Inserir → Gráfico de Pizza → Adicionar rótulos de dados
A31: Tipo de Controle | B31: Ativo Total (R$ bi) | C31: Participação (%) | D31: Nº Instituições
A32: Público | B32: 1.4 | C32: 22.7 | D32: 10
A33: Privado Nacional | B33: 3.2 | C33: 51.7 | D33: 53
A34: Privado Estrangeiro | B34: 1.6 | C34: 25.7 | D34: 36
A35: TOTAL | B35: =SUM(B32:B34) -> 6.2 | C35: =SUM(C32:C34) -> 100.1 | D35: =SUM(D32:D34) -> 99
A53: GRÁFICO 3 — Barras Horizontais: Top 10 Instituições por Ativo Total (R$ bi)
A54: Como criar: Selecione Instituição + Ativo → Inserir → Gráfico de Barras (horizontal) → Classificar do maior para o menor
A55: Instituição | B55: Ativo Total (R$ bi) | C55: Segmento | D55: Tipo de Controle
A56: BANCO NACIONAL DE DESENVOLVIME | B56: 0.9 | C56: S2 | D56: Público
A57: BTG PACTUAL | B57: 0.7 | C57: S1 | D57: Privado Nacional
A58: XP | B58: 0.3 | C58: S2 | D58: Privado Nacional
A59: SAFRA | B59: 0.3 | C59: S2 | D59: Privado Nacional
A60: NUBANK | B60: 0.2 | C60: S2 | D60: Privado Estrangeiro
A61: BANCO COOPERATIVO SICREDI S.A. | B61: 0.2 | C61: S2 | D61: Privado Nacional
A62: BANCO SICOOB | B62: 0.2 | C62: S2 | D62: Privado Nacional
A63: CITIBANK | B63: 0.2 | C63: S2 | D63: Privado Estrangeiro
A64: BANRISUL | B64: 0.2 | C64: S2 | D64: Público
A65: VOTORANTIM | B65: 0.1 | C65: S2 | D65: Privado Nacional
A83: Fonte: IF.data — Banco Central do Brasil — Setembro/2025 — Valores em R$ mil convertidos para R$ bilhões nos gráficos

Sheet Exerc_Graficos
A1: EXERCÍCIOS DE GRÁFICOS | Analista Júnior com IA — Módulo 3 | IF.data Set/2025
A2: Use os dados fornecidos em cada exercício para criar os gráficos indicados. Consulte a aba Exemplos_Graficos se precisar de referência.
A4: EXERCÍCIO 1 — Gráfico de Colunas: Ativo Total por Segmento
A5: 📋 Tarefa: Com base nos dados abaixo, crie um gráfico de colunas mostrando o Ativo Total
A6: médio (R$ bi) por segmento. Use cores diferentes para cada barra.
A7: 💡 Dica: Selecione as colunas Segmento e Ativo Médio → Inserir → Gráfico de Colunas → 2D Agrupado
A8: ❓ Pergunta de análise: Qual segmento tem maior ativo médio? O que isso revela sobre concentração?
A9: Segmento | B9: Ativo Médio (R$ bi) | C9: Ativo Total (R$ bi) | D9: Nº Instituições
A10: S1 | B10: 0.2 | C10: 0.9 | D10: 4
A11: S2 | B11: 0.3 | C11: 2.8 | D11: 11
A12: S3 | B12: 0 | C12: 2.2 | D12: 63
A13: S4 | B13: 0 | C13: 0.2 | D13: 18
A14: S5 | B14: 0 | C14: 0 | D14: 3
A16: → INSIRA SEU GRÁFICO AQUI (clique com botão direito → Mover Gráfico → Objeto na planilha → Exerc_Graficos)
A17: → RESPOSTA: O segmento ___ tem maior ativo médio. Isso indica que _________________________
A19: EXERCÍCIO 2 — Gráfico de Pizza: Distribuição de Instituições por Tipo de Controle
A20: 📋 Tarefa: Crie um gráfico de pizza mostrando a distribuição do NÚMERO de instituições
A21: por tipo de controle. Inclua rótulos de dados com percentuais.
A22: 💡 Dica: Selecione Tipo Controle + Nº Instituições → Inserir → Gráfico de Pizza
A23: ⚠ Atenção: Quantidade de instituições é diferente de participação no ativo. Qual conta mais?
A24: ❓ Pergunta de análise: Bancos privados são maioria em número. E em ativo total? Consulte Exemplos_Graficos.
A25: Tipo de Controle | B25: Nº Instituições | C25: Participação (%)
A26: Público | B26: 10 | C26: =B26/SUM(B26:B28)*100 -> 10.10101
A27: Privado Nacional | B27: 53 | C27: =B27/SUM(B26:B28)*100 -> 53.535354
A28: Privado Estrangeiro | B28: 36 | C28: =B28/SUM(B26:B28)*100 -> 36.363636
A29: TOTAL | B29: =SUM(B26:B28) -> 99 | C29: =SUM(C26:C28) -> 100
A31: → INSIRA SEU GRÁFICO AQUI
A32: → RESPOSTA: Em número, a maioria é ___. Em ativo total (ver Exemplos_Graficos), a concentração é ___.
A34: EXERCÍCIO 3 — Gráfico de Dispersão: ROE vs Ativo Total (Top 30)
A35: 📋 Tarefa: Com os dados das 30 maiores instituições, crie um gráfico de dispersão (XY)
A36: onde X = Ativo Total (R$ bi) e Y = ROE (%). Interprete o padrão.
A37: 💡 Dica: Selecione só as colunas Ativo e ROE (sem cabeçalho de texto) → Inserir → Dispersão → XY
A38: ❓ Pergunta: Bancos maiores têm ROE maior? Existe correlação positiva, negativa ou nenhuma?
A39: ⚠ Desafio: Identifique no gráfico o ponto que representa o maior banco. Que instituição é?
A40: Instituição | B40: Ativo Total (R$ bi) | C40: ROE (%) | D40: Segmento | E40: Tipo de Controle
A41: BANCO NACIONAL DE DESENVOLVIME | B41: 0.9 | C41: 2.31 | D41: S2 | E41: Público
A42: BTG PACTUAL | B42: 0.7 | C42: 6.37 | D42: S1 | E42: Privado Nacional
A43: XP | B43: 0.3 | C43: 1.69 | D43: S2 | E43: Privado Nacional
A44: SAFRA | B44: 0.3 | C44: 5.91 | D44: S2 | E44: Privado Nacional
A45: NUBANK | B45: 0.2 | C45: 17.92 | D45: S2 | E45: Privado Estrangeiro
...

Sheet Exerc.
A1: EXERCÍCIOS BÁSICOS | Fórmulas essenciais com dados reais do IF.data
A2: Nível: Iniciante | Use a aba Base_IFdata para consultar os dados | Todos os valores em R$ mil
A5: MEDIDAS DE RESUMO
A6: Nº | B6: O que fazer | C6: Sua fórmula aqui ↓ | D6: Resultado | E6: Para reflexão (responda com suas palavras)
A7: 1 | B7: Qual é o ATIVO TOTAL MÉDIO das 100 maiores instituições? → Coluna G da Base_IFdata | C7: MÉDIA(G5:G104) | D7: 62555242 | E7: 💡 Compara com a mediana. O que a diferença entre elas diz sobre a distribuição?
A8: 2 | B8: Qual é a MEDIANA do Ativo Total? → A mediana é mais representativa que a média neste caso? Por quê? | C8: MED(G5:G104) | D8: 21866853 | E8: 💡 Se a média for muito maior que a mediana, há concentração nos grandes bancos.
A9: 3 | B9: Qual é o MAIOR Ativo Total? Qual é o MENOR? → Use MÁXIMO e MÍNIMO | C9: MÁXIMO(G5:G104) MÍNIMO(G5:G104) | D9: 905220074 9522043 | E9: 💡 A diferença entre o maior e menor ativo mostra a concentração do setor.
A10: 4 | B10: Qual é o QUARTIL 1 (Q1) e QUARTIL 3 (Q3) da Carteira de Crédito? → Coluna H | C10: QUARTIL.EXC(H5:H104;1) QUARTIL.EXC(H5:H104;3) | D10: 5792380 22929973 | E10: 💡 Q1 e Q3 delimitam onde estão 50% das instituições do meio da distribuição.
A11: 5 | B11: Qual é o PERCENTIL 90 do Patrimônio Líquido? → Coluna L | C11: PERCENTIL.EXC(L5:L104;0,9) | D11: =Base_IFdata!M113 -> 12828046 | E11: 💡 90% das instituições têm PL abaixo deste valor. Só 10% estão acima.
A12: 6 | B12: Quantas agências existem no total? Qual é a média por instituição? → Coluna N | C12: SOMA(N5:N104) | D12: =Base_IFdata!O114 -> 2046 | E12: 💡 Compare com a mediana de agências. A distribuição é concentrada em poucos bancos?
A14: CONTAGEM E SOMA CONDICIONAL
A15: Nº | B15: O que fazer | C15: Sua fórmula aqui ↓ | D15: Resultado | E15: Para reflexão (responda com suas palavras)
A16: 7 | B16: Quantas instituições são de CONTROLE PÚBLICO (TC = 1)? → Coluna D da Base_IFdata | C16: CONT.SE(D5:D116;D5) | D16: 10 | E16: 💡 Bancos públicos são minoria em número, mas representam grande parte do ativo total.
A17: 8 | B17: Quantas instituições são do SEGMENTO S1? → Coluna C | C17: CONT.SE(C5:C117;C6) | D17: 4 | E17: 💡 O S1 concentra os bancos sistemicamente importantes: Itaú, BB, Caixa, Bradesco, Santander.
A18: 9 | B18: Qual é a SOMA do Ativo Total das instituições PÚBLICAS (TC = 1)? → Use SOMASE | C18: SOMASE(D5:D104;D5;G5:G104) | D18: =Base_IFdata!H119 -> 1391478284 | E18: 💡 Compare com a soma total. Qual % do ativo é público?
A19: 10 | B19: Qual é a MÉDIA da Carteira de Crédito das instituições PRIVADAS NACIONAIS (TC = 2)? → Use MÉDIASE | C19: MÉDIASE(D5:D104;D6;H5:H104) | D19: =Base_IFdata!I120 -> 21919416 | E19: 💡 Compare com a média das públicas e estrangeiras.
A20: 11 | B20: Quantas instituições de SP têm Lucro Líquido POSITIVO? → Use CONT.SES com duas condições | C20: CONT.SES(F5:F104;F8;M5:M104;">0") | D20: =Base_IFdata!N121 -> 51 | E20: 💡 SP concentra a maioria das sedes do sistema financeiro nacional.
A21: 12 | B21: Qual é o SOMA do Lucro Líquido das instituições de CONTROLE ESTRANGEIRO (TC = 3)? → Use SOMASE | C21: SOMASE(D5:D104;D9;M5:M104) | D21: =Base_IFdata!N122 -> 9215214 | E21: 💡 Bancos estrangeiros têm lucros altos mesmo com carteiras menores?
A23: CLASSIFICAÇÃO E LÓGICA
A24: Nº | B24: O que fazer | C24: Sua fórmula aqui ↓ | D24: Resultado | E24: Para reflexão (responda com suas palavras)
A25: 13 | B25: Na coluna ao lado, classifique cada instituição: 'Grande' se Ativo > 100 bilhões, senão 'Média/Pequena' → Use SE (100 bi = 100.000.000 em R$ mil) | C25: SE(H6>= 100000000; "Grande"; "Média/Pequena" ) | E25: 💡 Quantas são 'Grandes'? Esse grupo representa qual % do ativo total?
A26: 14 | B26: Classifique o ROE (coluna S): 'Excelente' se > 15%, 'Bom' se > 8%, 'Fraco' se > 0%, 'Prejuízo' se ≤ 0% → Use SES | C26: SES(T5:T104>15%;"Excelente";T5:T104>8%;"Bom";T5:T104>0%;"Fraco";T5:T104<=0%;"Prejuizo") | E26: 💡 Quantas instituições têm ROE 'Excelente'? São os bancos que você esperaria?
A27: 15 | B27: Use PROCV para buscar o Ativo Total do NUBANK → A chave é o nome na coluna A da Base_IFdata | C27: PROCV(Base_IFdata!A9;Base_IFdata!A5:G104;7;FALSO) | D27: 219449385 | E27: 💡 Agora busque o Patrimônio Líquido e o Lucro Líquido do Nubank com PROCV.

Sheet Exerc_Intermediário
A1: EXERCÍCIOS INTERMEDIÁRIOS | Análise aprofundada com dados reais do IF.data
A2: Nível: Intermediário | Requer conclusão dos exercícios básicos | Use Claude.ai para discutir suas interpretações
A5: ANÁLISE COMPARATIVA POR SEGMENTO
A6: Nº | B6: O que fazer | C6: Sua resposta / fórmula | D6: Resultado | E6: Reflexão
A7: 1 | B7: Monte uma tabela comparativa: para cada segmento (S1 a S5), calcule: a) Qtd de instituições b) Soma do Ativo Total c) Média da Carteira de Crédito d) Soma do Lucro Líquido → Use CONT.SE, SOMASE e MÉDIASE para cada segmento | C7: ← escreva aqui | E7: 💡 Qual segmento concentra mais ativos? E mais lucro? A distribuição é equilibrada?
A8: 2 | B8: Compare o ROE médio por tipo de controle: a) Público (TC=1) b) Privado Nacional (TC=2) c) Privado Estrangeiro (TC=3) → Use MÉDIASE na coluna S (ROE) | C8: ← escreva aqui | E8: 💡 Qual tipo de controle gera maior retorno para os acionistas? Isso surpreende você?
A9: 3 | B9: Calcule a participação de mercado de cada tipo de controle no Ativo Total: % Público = Soma Ativo Público / Soma Ativo Total × 100 → Use SOMASE e operações simples | C9: ← escreva aqui | E9: 💡 A concentração bancária está nos bancos públicos ou privados? Compare com outros países.
A11: ANÁLISE DE EFICIÊNCIA E RENTABILIDADE
A12: Nº | B12: O que fazer | C12: Sua resposta / fórmula | D12: Resultado | E12: Reflexão
A13: 4 | B13: Identifique as 5 instituições com MAIOR ROE na base. → Use ORDEM ou ordene manualmente | C13: ← escreva aqui | E13: 💡 As mais rentáveis são os maiores bancos ou instituições menores?
A14: 5 | B14: Calcule o Índice de Alavancagem (Passivo / PL) para cada instituição. → Crie fórmula na coluna ao lado: =Passivo/Patrimônio Líquido | C14: ← escreva aqui | E14: 💡 Alavancagem alta pode indicar maior risco. Quem tem a maior alavancagem?
A15: 6 | B15: Quais instituições têm Carteira de Crédito MAIOR que o Patrimônio Líquido por um fator de 10 ou mais? → Use CONT.SES com condição relativa | C15: ← escreva aqui | E15: 💡 Alta relação crédito/PL é comum em bancos de varejo. É um sinal de risco?
A17: ANÁLISE REGIONAL E ESTRUTURAL
A18: Nº | B18: O que fazer | C18: Sua resposta / fórmula | D18: Resultado | E18: Reflexão
A19: 7 | B19: Quantas instituições com sede em SP têm Ativo acima de R$ 1 bilhão (= 1.000.000 em R$ mil)? → Use CONT.SES com UF='SP' e Ativo>1000000 | C19: ← escreva aqui | E19: 💡 SP concentra as maiores instituições. Que % do total isso representa?
A20: 8 | B20: Qual é a soma do Ativo Total das instituições DIGITAIS (sem agências físicas, ou seja, Agências = 0)? → Use SOMASE com condição Agências=0 | C20: ← escreva aqui | E20: 💡 As fintechs sem agências já representam quanto do sistema financeiro?
A21: 9 | B21: Monte um resumo: quantas instituições de cada UF estão na base? → Use CONT.SE para as principais UFs: SP, MG, RS, RJ, PR | C21: ← escreva aqui | E21: 💡 A distribuição geográfica reflete o PIB de cada estado?
A23: INSIGHT FINAL – ESCREVA SUA ANÁLISE
A24: Nº | B24: O que fazer | C24: Sua resposta / fórmula | D24: Resultado | E24: Reflexão
A25: 10 | B25: Com base em todos os exercícios anteriores, escreva sua análise respondendo: 1. Qual é o perfil do sistema financeiro brasileiro segundo esta base? 2. Qual insight mais te surpreendeu? 3. Se você fosse apresentar isso para um diretor em 2 minutos, o que diria? → Use a aba Template_Análise para organizar sua resposta | C25: ← escreva aqui | E25: 💡 Use o Claude.ai: cole seus insights e peça 'Transforme isso em uma análise executiva de 3 parágrafos'.

Sheet Template_Análise
A1: TEMPLATE DE ANÁLISE | Preencha com base nos dados do IF.data
A4: 1. CONTEXTO DA ANÁLISE
A5: Pergunta que vou responder:
A6: Por que essa análise importa?
A7: Base de dados utilizada: | B7: IF.data – Banco Central do Brasil – Setembro/2025
A8: Período analisado:
A10: 2. PRINCIPAIS INDICADORES
A11: Ativo Total do sistema (Top 100):
A12: Participação pública no ativo total (%):
A13: ROE médio do sistema:
A14: Mediana da Carteira de Crédito:
A15: Número de instituições sem agências físicas:
A17: 3. INSIGHT PRINCIPAL (em uma frase)
A18: Insight:
A19: Evidência 1:
A20: Evidência 2:
A22: 4. IMPLICAÇÕES
... A29: Análise que faria com mais tempo:
